Traceback (most recent call last):
  File "c:\users\dudas\anaconda3\envs\wintest\lib\site-packages\jupyter_cache\executors\utils.py", line 56, in single_nb_execution
    record_timing=False,
  File "c:\users\dudas\anaconda3\envs\wintest\lib\site-packages\nbclient\client.py", line 1112, in execute
    return NotebookClient(nb=nb, resources=resources, km=km, **kwargs).execute()
  File "c:\users\dudas\anaconda3\envs\wintest\lib\site-packages\nbclient\util.py", line 74, in wrapped
    return just_run(coro(*args, **kwargs))
  File "c:\users\dudas\anaconda3\envs\wintest\lib\site-packages\nbclient\util.py", line 53, in just_run
    return loop.run_until_complete(coro)
  File "c:\users\dudas\anaconda3\envs\wintest\lib\asyncio\base_events.py", line 587, in run_until_complete
    return future.result()
  File "c:\users\dudas\anaconda3\envs\wintest\lib\site-packages\nbclient\client.py", line 554, in async_execute
    cell, index, execution_count=self.code_cells_executed + 1
  File "c:\users\dudas\anaconda3\envs\wintest\lib\site-packages\nbclient\client.py", line 857, in async_execute_cell
    self._check_raise_for_error(cell, exec_reply)
  File "c:\users\dudas\anaconda3\envs\wintest\lib\site-packages\nbclient\client.py", line 760, in _check_raise_for_error
    raise CellExecutionError.from_cell_and_msg(cell, exec_reply_content)
nbclient.exceptions.CellExecutionError: An error occurred while executing the following cell:
------------------
birthdayMonths = [4,2,11,9,15]
birthdayDays = [6,12,24,23,15]
birthdayYears = [1955,1983,1999,2010,2015]

# Cycle through all of the birthdays and print out 
for spot in range(len(birthdayDays)):
    print ( "\n#-# Spot = ", spot )
    # Print using get, which has built in error checking
    print( monthSwap.get(birthdayMonths[spot],"oooooops!"), birthdayDays[spot], birthdayYears[spot] )
    # Print without get, which gives an error if passed a key that doesn't exist
    print( monthSwap[birthdayMonths[spot]], birthdayDays[spot], birthdayYears[spot] )
------------------

[1;31m---------------------------------------------------------------------------[0m
[1;31mKeyError[0m                                  Traceback (most recent call last)
[1;32m<ipython-input-15-b2157a63f782>[0m in [0;36m<module>[1;34m[0m
[0;32m      9[0m     [0mprint[0m[1;33m([0m [0mmonthSwap[0m[1;33m.[0m[0mget[0m[1;33m([0m[0mbirthdayMonths[0m[1;33m[[0m[0mspot[0m[1;33m][0m[1;33m,[0m[1;34m"oooooops!"[0m[1;33m)[0m[1;33m,[0m [0mbirthdayDays[0m[1;33m[[0m[0mspot[0m[1;33m][0m[1;33m,[0m [0mbirthdayYears[0m[1;33m[[0m[0mspot[0m[1;33m][0m [1;33m)[0m[1;33m[0m[1;33m[0m[0m
[0;32m     10[0m     [1;31m# Print without get, which gives an error if passed a key that doesn't exist[0m[1;33m[0m[1;33m[0m[1;33m[0m[0m
[1;32m---> 11[1;33m     [0mprint[0m[1;33m([0m [0mmonthSwap[0m[1;33m[[0m[0mbirthdayMonths[0m[1;33m[[0m[0mspot[0m[1;33m][0m[1;33m][0m[1;33m,[0m [0mbirthdayDays[0m[1;33m[[0m[0mspot[0m[1;33m][0m[1;33m,[0m [0mbirthdayYears[0m[1;33m[[0m[0mspot[0m[1;33m][0m [1;33m)[0m[1;33m[0m[1;33m[0m[0m
[0m
[1;31mKeyError[0m: 15
KeyError: 15

