Traceback (most recent call last):
  File "/home/dudaspm/anaconda3/envs/jupyterbook/lib/python3.9/site-packages/jupyter_cache/executors/utils.py", line 58, in single_nb_execution
    executenb(
  File "/home/dudaspm/anaconda3/envs/jupyterbook/lib/python3.9/site-packages/nbclient/client.py", line 1319, in execute
    return NotebookClient(nb=nb, resources=resources, km=km, **kwargs).execute()
  File "/home/dudaspm/anaconda3/envs/jupyterbook/lib/python3.9/site-packages/jupyter_core/utils/__init__.py", line 165, in wrapped
    return loop.run_until_complete(inner)
  File "/home/dudaspm/anaconda3/envs/jupyterbook/lib/python3.9/asyncio/base_events.py", line 647, in run_until_complete
    return future.result()
  File "/home/dudaspm/anaconda3/envs/jupyterbook/lib/python3.9/site-packages/nbclient/client.py", line 709, in async_execute
    await self.async_execute_cell(
  File "/home/dudaspm/anaconda3/envs/jupyterbook/lib/python3.9/site-packages/nbclient/client.py", line 1062, in async_execute_cell
    await self._check_raise_for_error(cell, cell_index, exec_reply)
  File "/home/dudaspm/anaconda3/envs/jupyterbook/lib/python3.9/site-packages/nbclient/client.py", line 918, in _check_raise_for_error
    raise CellExecutionError.from_cell_and_msg(cell, exec_reply_content)
nbclient.exceptions.CellExecutionError: An error occurred while executing the following cell:
------------------
b = pd.DataFrame([[1, 2, 3],[4, 5, 6]])
b.columns = ['name1','name2','name3'] 
print(b)
------------------


[0;31m---------------------------------------------------------------------------[0m
[0;31mNameError[0m                                 Traceback (most recent call last)
Cell [0;32mIn[8], line 1[0m
[0;32m----> 1[0m b [38;5;241m=[39m [43mpd[49m[38;5;241m.[39mDataFrame([[[38;5;241m1[39m, [38;5;241m2[39m, [38;5;241m3[39m],[[38;5;241m4[39m, [38;5;241m5[39m, [38;5;241m6[39m]])
[1;32m      2[0m b[38;5;241m.[39mcolumns [38;5;241m=[39m [[38;5;124m'[39m[38;5;124mname1[39m[38;5;124m'[39m,[38;5;124m'[39m[38;5;124mname2[39m[38;5;124m'[39m,[38;5;124m'[39m[38;5;124mname3[39m[38;5;124m'[39m] 
[1;32m      3[0m [38;5;28mprint[39m(b)

[0;31mNameError[0m: name 'pd' is not defined

